2024-02-20 11:32:50,181 - INFO - [31m[1mWARNING: This is a development server. Do not use it in a production deployment. Use a production WSGI server instead.[0m
 * Running on all addresses (0.0.0.0)
 * Running on http://127.0.0.1:5000
 * Running on http://10.106.67.2:5000
2024-02-20 11:32:50,181 - INFO - [33mPress CTRL+C to quit[0m
2024-02-20 11:32:52,950 - INFO - XKNX v2.11.2 starting tunneling connection to KNX bus.
2024-02-20 11:32:53,197 - INFO - 127.0.0.1 - - [20/Feb/2024 11:32:53] "POST /api/readgroup HTTP/1.1" 200 -
2024-02-20 11:33:12,469 - INFO - XKNX v2.11.2 starting tunneling connection to KNX bus.
2024-02-20 11:33:12,595 - ERROR - Unexpected error while processing outgoing telegram <Telegram direction="Outgoing" source_address="0.0.4" destination_address="0/0/6" payload="<GroupValueRead />" />
Traceback (most recent call last):
  File "/usr/lib/python3.11/site-packages/xknx/core/telegram_queue.py", line 169, in _outgoing_rate_limiter
    await self.process_telegram_outgoing(telegram)
  File "/usr/lib/python3.11/site-packages/xknx/core/telegram_queue.py", line 205, in process_telegram_outgoing
    await self.xknx.cemi_handler.send_telegram(telegram)
  File "/usr/lib/python3.11/site-packages/xknx/cemi/cemi_handler.py", line 82, in send_telegram
    await self._l_data_confirmation_event.wait()
  File "/usr/lib/python3.11/asyncio/locks.py", line 210, in wait
    fut = self._get_loop().create_future()
          ^^^^^^^^^^^^^^^^
  File "/usr/lib/python3.11/asyncio/mixins.py", line 20, in _get_loop
    raise RuntimeError(f'{self!r} is bound to a different event loop')
RuntimeError: <asyncio.locks.Event object at 0x79d7a2cea6d0 [unset]> is bound to a different event loop
2024-02-20 11:33:14,537 - WARNING - Error: KNX bus did not respond in time (2.0 secs) to GroupValueRead request for: 0/0/6
2024-02-20 11:33:14,537 - ERROR - Nothing to read, give up.
2024-02-20 11:33:14,538 - ERROR - Exception on /api/readgroup [POST]
Traceback (most recent call last):
  File "/usr/lib/python3.11/site-packages/flask/app.py", line 2190, in wsgi_app
    response = self.full_dispatch_request()
               ^^^^^^^^^^^^^^^^^^^^^^^^^^^^
  File "/usr/lib/python3.11/site-packages/flask/app.py", line 1486, in full_dispatch_request
    rv = self.handle_user_exception(e)
         ^^^^^^^^^^^^^^^^^^^^^^^^^^^^^
  File "/usr/lib/python3.11/site-packages/flask/app.py", line 1484, in full_dispatch_request
    rv = self.dispatch_request()
         ^^^^^^^^^^^^^^^^^^^^^^^
  File "/usr/lib/python3.11/site-packages/flask/app.py", line 1469, in dispatch_request
    return self.ensure_sync(self.view_functions[rule.endpoint])(**view_args)
           ^^^^^^^^^^^^^^^^^^^^^^^^^^^^^^^^^^^^^^^^^^^^^^^^^^^^^^^^^^^^^^^^^
  File "/usr/lib/python3.11/site-packages/asgiref/sync.py", line 277, in __call__
    return call_result.result()
           ^^^^^^^^^^^^^^^^^^^^
  File "/usr/lib/python3.11/concurrent/futures/_base.py", line 449, in result
    return self.__get_result()
           ^^^^^^^^^^^^^^^^^^^
  File "/usr/lib/python3.11/concurrent/futures/_base.py", line 401, in __get_result
    raise self._exception
  File "/usr/lib/python3.11/site-packages/asgiref/sync.py", line 353, in main_wrap
    result = await self.awaitable(*args, **kwargs)
             ^^^^^^^^^^^^^^^^^^^^^^^^^^^^^^^^^^^^^
  File "/home/amenia/Documents/Projekte/pyknx-con/main.py", line 63, in apiReadGroup
    "val": await read_group(data['group_address'], data['format'])
           ^^^^^^^^^^^^^^^^^^^^^^^^^^^^^^^^^^^^^^^^^^^^^^^^^^^^^^^
  File "/home/amenia/Documents/Projekte/pyknx-con/main.py", line 50, in read_group
    async with xknx:
  File "/usr/lib/python3.11/site-packages/xknx/xknx.py", line 113, in __aexit__
    await self.stop()
  File "/usr/lib/python3.11/site-packages/xknx/xknx.py", line 140, in stop
    await self.join()
  File "/usr/lib/python3.11/site-packages/xknx/xknx.py", line 134, in join
    await self.telegrams.join()
  File "/usr/lib/python3.11/asyncio/queues.py", line 215, in join
    await self._finished.wait()
  File "/usr/lib/python3.11/asyncio/locks.py", line 210, in wait
    fut = self._get_loop().create_future()
          ^^^^^^^^^^^^^^^^
  File "/usr/lib/python3.11/asyncio/mixins.py", line 20, in _get_loop
    raise RuntimeError(f'{self!r} is bound to a different event loop')
RuntimeError: <asyncio.locks.Event object at 0x79d7a2cea590 [unset]> is bound to a different event loop
2024-02-20 11:33:14,542 - INFO - 127.0.0.1 - - [20/Feb/2024 11:33:14] "[35m[1mPOST /api/readgroup HTTP/1.1[0m" 500 -
2024-02-20 11:34:41,770 - INFO - XKNX v2.11.2 starting tunneling connection to KNX bus.
2024-02-20 11:34:41,837 - ERROR - _GatheringFuture exception was never retrieved
future: <_GatheringFuture finished exception=RuntimeError('<Queue at 0x79d7a2cea550 maxsize=0 tasks=1> is bound to a different event loop')>
Traceback (most recent call last):
  File "/usr/lib/python3.11/site-packages/xknx/core/telegram_queue.py", line 119, in _telegram_consumer
    telegram = await self.xknx.telegrams.get()
               ^^^^^^^^^^^^^^^^^^^^^^^^^^^^^^^
  File "/usr/lib/python3.11/asyncio/queues.py", line 155, in get
    getter = self._get_loop().create_future()
             ^^^^^^^^^^^^^^^^
  File "/usr/lib/python3.11/asyncio/mixins.py", line 20, in _get_loop
    raise RuntimeError(f'{self!r} is bound to a different event loop')
RuntimeError: <Queue at 0x79d7a2cea550 maxsize=0 tasks=1> is bound to a different event loop
2024-02-20 11:34:41,839 - ERROR - Exception on /api/readgroup [POST]
Traceback (most recent call last):
  File "/usr/lib/python3.11/site-packages/flask/app.py", line 2190, in wsgi_app
    response = self.full_dispatch_request()
               ^^^^^^^^^^^^^^^^^^^^^^^^^^^^
  File "/usr/lib/python3.11/site-packages/flask/app.py", line 1486, in full_dispatch_request
    rv = self.handle_user_exception(e)
         ^^^^^^^^^^^^^^^^^^^^^^^^^^^^^
  File "/usr/lib/python3.11/site-packages/flask/app.py", line 1484, in full_dispatch_request
    rv = self.dispatch_request()
         ^^^^^^^^^^^^^^^^^^^^^^^
  File "/usr/lib/python3.11/site-packages/flask/app.py", line 1469, in dispatch_request
    return self.ensure_sync(self.view_functions[rule.endpoint])(**view_args)
           ^^^^^^^^^^^^^^^^^^^^^^^^^^^^^^^^^^^^^^^^^^^^^^^^^^^^^^^^^^^^^^^^^
  File "/usr/lib/python3.11/site-packages/asgiref/sync.py", line 277, in __call__
    return call_result.result()
           ^^^^^^^^^^^^^^^^^^^^
  File "/usr/lib/python3.11/concurrent/futures/_base.py", line 449, in result
    return self.__get_result()
           ^^^^^^^^^^^^^^^^^^^
  File "/usr/lib/python3.11/concurrent/futures/_base.py", line 401, in __get_result
    raise self._exception
  File "/usr/lib/python3.11/site-packages/asgiref/sync.py", line 353, in main_wrap
    result = await self.awaitable(*args, **kwargs)
             ^^^^^^^^^^^^^^^^^^^^^^^^^^^^^^^^^^^^^
  File "/home/amenia/Documents/Projekte/pyknx-con/main.py", line 63, in apiReadGroup
    "val": await read_group(data['group_address'], data['format'])
           ^^^^^^^^^^^^^^^^^^^^^^^^^^^^^^^^^^^^^^^^^^^^^^^^^^^^^^^
  File "/home/amenia/Documents/Projekte/pyknx-con/main.py", line 50, in read_group
    async with xknx:
  File "/usr/lib/python3.11/site-packages/xknx/xknx.py", line 113, in __aexit__
    await self.stop()
  File "/usr/lib/python3.11/site-packages/xknx/xknx.py", line 140, in stop
    await self.join()
  File "/usr/lib/python3.11/site-packages/xknx/xknx.py", line 134, in join
    await self.telegrams.join()
  File "/usr/lib/python3.11/asyncio/queues.py", line 215, in join
    await self._finished.wait()
  File "/usr/lib/python3.11/asyncio/locks.py", line 210, in wait
    fut = self._get_loop().create_future()
          ^^^^^^^^^^^^^^^^
  File "/usr/lib/python3.11/asyncio/mixins.py", line 20, in _get_loop
    raise RuntimeError(f'{self!r} is bound to a different event loop')
RuntimeError: <asyncio.locks.Event object at 0x79d7a2cea590 [unset]> is bound to a different event loop
2024-02-20 11:34:41,841 - INFO - 127.0.0.1 - - [20/Feb/2024 11:34:41] "[35m[1mPOST /api/readgroup HTTP/1.1[0m" 500 -
2024-02-20 11:34:43,995 - INFO - XKNX v2.11.2 starting tunneling connection to KNX bus.
2024-02-20 11:34:44,058 - ERROR - _GatheringFuture exception was never retrieved
future: <_GatheringFuture finished exception=RuntimeError('<Queue at 0x79d7a2cea610 maxsize=0> is bound to a different event loop')>
Traceback (most recent call last):
  File "/usr/lib/python3.11/site-packages/xknx/core/telegram_queue.py", line 150, in _outgoing_rate_limiter
    telegram = await self.outgoing_queue.get()
               ^^^^^^^^^^^^^^^^^^^^^^^^^^^^^^^
  File "/usr/lib/python3.11/asyncio/queues.py", line 155, in get
    getter = self._get_loop().create_future()
             ^^^^^^^^^^^^^^^^
  File "/usr/lib/python3.11/asyncio/mixins.py", line 20, in _get_loop
    raise RuntimeError(f'{self!r} is bound to a different event loop')
RuntimeError: <Queue at 0x79d7a2cea610 maxsize=0> is bound to a different event loop
2024-02-20 11:34:44,119 - ERROR - Unexpected error while processing outgoing telegram <Telegram direction="Outgoing" source_address="0.0.5" destination_address="0/0/6" payload="<GroupValueRead />" />
Traceback (most recent call last):
  File "/usr/lib/python3.11/site-packages/xknx/core/telegram_queue.py", line 169, in _outgoing_rate_limiter
    await self.process_telegram_outgoing(telegram)
  File "/usr/lib/python3.11/site-packages/xknx/core/telegram_queue.py", line 205, in process_telegram_outgoing
    await self.xknx.cemi_handler.send_telegram(telegram)
  File "/usr/lib/python3.11/site-packages/xknx/cemi/cemi_handler.py", line 82, in send_telegram
    await self._l_data_confirmation_event.wait()
  File "/usr/lib/python3.11/asyncio/locks.py", line 210, in wait
    fut = self._get_loop().create_future()
          ^^^^^^^^^^^^^^^^
  File "/usr/lib/python3.11/asyncio/mixins.py", line 20, in _get_loop
    raise RuntimeError(f'{self!r} is bound to a different event loop')
RuntimeError: <asyncio.locks.Event object at 0x79d7a2cea6d0 [unset]> is bound to a different event loop
2024-02-20 11:34:46,060 - WARNING - Error: KNX bus did not respond in time (2.0 secs) to GroupValueRead request for: 0/0/6
2024-02-20 11:34:46,060 - ERROR - Nothing to read, give up.
2024-02-20 11:34:46,061 - ERROR - Exception on /api/readgroup [POST]
Traceback (most recent call last):
  File "/usr/lib/python3.11/site-packages/flask/app.py", line 2190, in wsgi_app
    response = self.full_dispatch_request()
               ^^^^^^^^^^^^^^^^^^^^^^^^^^^^
  File "/usr/lib/python3.11/site-packages/flask/app.py", line 1486, in full_dispatch_request
    rv = self.handle_user_exception(e)
         ^^^^^^^^^^^^^^^^^^^^^^^^^^^^^
  File "/usr/lib/python3.11/site-packages/flask/app.py", line 1484, in full_dispatch_request
    rv = self.dispatch_request()
         ^^^^^^^^^^^^^^^^^^^^^^^
  File "/usr/lib/python3.11/site-packages/flask/app.py", line 1469, in dispatch_request
    return self.ensure_sync(self.view_functions[rule.endpoint])(**view_args)
           ^^^^^^^^^^^^^^^^^^^^^^^^^^^^^^^^^^^^^^^^^^^^^^^^^^^^^^^^^^^^^^^^^
  File "/usr/lib/python3.11/site-packages/asgiref/sync.py", line 277, in __call__
    return call_result.result()
           ^^^^^^^^^^^^^^^^^^^^
  File "/usr/lib/python3.11/concurrent/futures/_base.py", line 449, in result
    return self.__get_result()
           ^^^^^^^^^^^^^^^^^^^
  File "/usr/lib/python3.11/concurrent/futures/_base.py", line 401, in __get_result
    raise self._exception
  File "/usr/lib/python3.11/site-packages/asgiref/sync.py", line 353, in main_wrap
    result = await self.awaitable(*args, **kwargs)
             ^^^^^^^^^^^^^^^^^^^^^^^^^^^^^^^^^^^^^
  File "/home/amenia/Documents/Projekte/pyknx-con/main.py", line 63, in apiReadGroup
    "val": await read_group(data['group_address'], data['format'])
           ^^^^^^^^^^^^^^^^^^^^^^^^^^^^^^^^^^^^^^^^^^^^^^^^^^^^^^^
  File "/home/amenia/Documents/Projekte/pyknx-con/main.py", line 50, in read_group
    async with xknx:
  File "/usr/lib/python3.11/site-packages/xknx/xknx.py", line 113, in __aexit__
    await self.stop()
  File "/usr/lib/python3.11/site-packages/xknx/xknx.py", line 140, in stop
    await self.join()
  File "/usr/lib/python3.11/site-packages/xknx/xknx.py", line 134, in join
    await self.telegrams.join()
  File "/usr/lib/python3.11/asyncio/queues.py", line 215, in join
    await self._finished.wait()
  File "/usr/lib/python3.11/asyncio/locks.py", line 210, in wait
    fut = self._get_loop().create_future()
          ^^^^^^^^^^^^^^^^
  File "/usr/lib/python3.11/asyncio/mixins.py", line 20, in _get_loop
    raise RuntimeError(f'{self!r} is bound to a different event loop')
RuntimeError: <asyncio.locks.Event object at 0x79d7a2cea590 [unset]> is bound to a different event loop
2024-02-20 11:34:46,062 - INFO - 127.0.0.1 - - [20/Feb/2024 11:34:46] "[35m[1mPOST /api/readgroup HTTP/1.1[0m" 500 -
2024-02-20 11:35:42,191 - WARNING - Could not close loop, reason: <asyncio.locks.Event object at 0x79d7a2cea590 [unset]> is bound to a different event loop
2024-02-20 11:35:42,191 - ERROR - _GatheringFuture exception was never retrieved
future: <_GatheringFuture finished exception=RuntimeError('<Queue at 0x79d7a2cea550 maxsize=0 tasks=2> is bound to a different event loop')>
Traceback (most recent call last):
  File "/usr/lib/python3.11/site-packages/xknx/core/telegram_queue.py", line 119, in _telegram_consumer
    telegram = await self.xknx.telegrams.get()
               ^^^^^^^^^^^^^^^^^^^^^^^^^^^^^^^
  File "/usr/lib/python3.11/asyncio/queues.py", line 155, in get
    getter = self._get_loop().create_future()
             ^^^^^^^^^^^^^^^^
  File "/usr/lib/python3.11/asyncio/mixins.py", line 20, in _get_loop
    raise RuntimeError(f'{self!r} is bound to a different event loop')
RuntimeError: <Queue at 0x79d7a2cea550 maxsize=0 tasks=2> is bound to a different event loop
2024-02-20 11:35:43,231 - INFO - [31m[1mWARNING: This is a development server. Do not use it in a production deployment. Use a production WSGI server instead.[0m
 * Running on all addresses (0.0.0.0)
 * Running on http://127.0.0.1:5000
 * Running on http://10.106.67.2:5000
2024-02-20 11:35:43,232 - INFO - [33mPress CTRL+C to quit[0m
2024-02-20 11:35:46,479 - INFO - XKNX v2.11.2 starting tunneling connection to KNX bus.
2024-02-20 11:35:46,722 - INFO - 127.0.0.1 - - [20/Feb/2024 11:35:46] "POST /api/readgroup HTTP/1.1" 200 -
2024-02-20 11:35:47,526 - INFO - XKNX v2.11.2 starting tunneling connection to KNX bus.
2024-02-20 11:35:47,647 - ERROR - Unexpected error while processing outgoing telegram <Telegram direction="Outgoing" source_address="0.0.8" destination_address="0/0/6" payload="<GroupValueRead />" />
Traceback (most recent call last):
  File "/usr/lib/python3.11/site-packages/xknx/core/telegram_queue.py", line 169, in _outgoing_rate_limiter
    await self.process_telegram_outgoing(telegram)
  File "/usr/lib/python3.11/site-packages/xknx/core/telegram_queue.py", line 205, in process_telegram_outgoing
    await self.xknx.cemi_handler.send_telegram(telegram)
  File "/usr/lib/python3.11/site-packages/xknx/cemi/cemi_handler.py", line 82, in send_telegram
    await self._l_data_confirmation_event.wait()
  File "/usr/lib/python3.11/asyncio/locks.py", line 210, in wait
    fut = self._get_loop().create_future()
          ^^^^^^^^^^^^^^^^
  File "/usr/lib/python3.11/asyncio/mixins.py", line 20, in _get_loop
    raise RuntimeError(f'{self!r} is bound to a different event loop')
RuntimeError: <asyncio.locks.Event object at 0x707e421eab10 [unset]> is bound to a different event loop
2024-02-20 11:35:49,590 - WARNING - Error: KNX bus did not respond in time (2.0 secs) to GroupValueRead request for: 0/0/6
2024-02-20 11:35:49,590 - ERROR - Nothing to read, give up.
2024-02-20 11:35:49,591 - ERROR - Exception on /api/readgroup [POST]
Traceback (most recent call last):
  File "/usr/lib/python3.11/site-packages/flask/app.py", line 2190, in wsgi_app
    response = self.full_dispatch_request()
               ^^^^^^^^^^^^^^^^^^^^^^^^^^^^
  File "/usr/lib/python3.11/site-packages/flask/app.py", line 1486, in full_dispatch_request
    rv = self.handle_user_exception(e)
         ^^^^^^^^^^^^^^^^^^^^^^^^^^^^^
  File "/usr/lib/python3.11/site-packages/flask/app.py", line 1484, in full_dispatch_request
    rv = self.dispatch_request()
         ^^^^^^^^^^^^^^^^^^^^^^^
  File "/usr/lib/python3.11/site-packages/flask/app.py", line 1469, in dispatch_request
    return self.ensure_sync(self.view_functions[rule.endpoint])(**view_args)
           ^^^^^^^^^^^^^^^^^^^^^^^^^^^^^^^^^^^^^^^^^^^^^^^^^^^^^^^^^^^^^^^^^
  File "/usr/lib/python3.11/site-packages/asgiref/sync.py", line 277, in __call__
    return call_result.result()
           ^^^^^^^^^^^^^^^^^^^^
  File "/usr/lib/python3.11/concurrent/futures/_base.py", line 449, in result
    return self.__get_result()
           ^^^^^^^^^^^^^^^^^^^
  File "/usr/lib/python3.11/concurrent/futures/_base.py", line 401, in __get_result
    raise self._exception
  File "/usr/lib/python3.11/site-packages/asgiref/sync.py", line 353, in main_wrap
    result = await self.awaitable(*args, **kwargs)
             ^^^^^^^^^^^^^^^^^^^^^^^^^^^^^^^^^^^^^
  File "/home/amenia/Documents/Projekte/pyknx-con/main.py", line 63, in apiReadGroup
    "val": await read_group(data['group_address'], data['format'])
           ^^^^^^^^^^^^^^^^^^^^^^^^^^^^^^^^^^^^^^^^^^^^^^^^^^^^^^^
  File "/home/amenia/Documents/Projekte/pyknx-con/main.py", line 50, in read_group
    async with xknx:
  File "/usr/lib/python3.11/site-packages/xknx/xknx.py", line 113, in __aexit__
    await self.stop()
  File "/usr/lib/python3.11/site-packages/xknx/xknx.py", line 140, in stop
    await self.join()
  File "/usr/lib/python3.11/site-packages/xknx/xknx.py", line 134, in join
    await self.telegrams.join()
  File "/usr/lib/python3.11/asyncio/queues.py", line 215, in join
    await self._finished.wait()
  File "/usr/lib/python3.11/asyncio/locks.py", line 210, in wait
    fut = self._get_loop().create_future()
          ^^^^^^^^^^^^^^^^
  File "/usr/lib/python3.11/asyncio/mixins.py", line 20, in _get_loop
    raise RuntimeError(f'{self!r} is bound to a different event loop')
RuntimeError: <asyncio.locks.Event object at 0x707e421eaa10 [unset]> is bound to a different event loop
2024-02-20 11:35:49,595 - INFO - 127.0.0.1 - - [20/Feb/2024 11:35:49] "[35m[1mPOST /api/readgroup HTTP/1.1[0m" 500 -
2024-02-20 11:36:09,450 - WARNING - Could not close loop, reason: <asyncio.locks.Event object at 0x707e421eaa10 [unset]> is bound to a different event loop
2024-02-20 11:36:09,451 - ERROR - _GatheringFuture exception was never retrieved
future: <_GatheringFuture finished exception=RuntimeError('<Queue at 0x707e421ea9d0 maxsize=0 tasks=1> is bound to a different event loop')>
Traceback (most recent call last):
  File "/usr/lib/python3.11/site-packages/xknx/core/telegram_queue.py", line 119, in _telegram_consumer
    telegram = await self.xknx.telegrams.get()
               ^^^^^^^^^^^^^^^^^^^^^^^^^^^^^^^
  File "/usr/lib/python3.11/asyncio/queues.py", line 155, in get
    getter = self._get_loop().create_future()
             ^^^^^^^^^^^^^^^^
  File "/usr/lib/python3.11/asyncio/mixins.py", line 20, in _get_loop
    raise RuntimeError(f'{self!r} is bound to a different event loop')
RuntimeError: <Queue at 0x707e421ea9d0 maxsize=0 tasks=1> is bound to a different event loop
INFO:werkzeug:[31m[1mWARNING: This is a development server. Do not use it in a production deployment. Use a production WSGI server instead.[0m
 * Running on all addresses (0.0.0.0)
 * Running on http://127.0.0.1:5000
 * Running on http://10.106.67.2:5000
INFO:werkzeug:[33mPress CTRL+C to quit[0m
INFO:werkzeug: * Restarting with stat
WARNING:werkzeug: * Debugger is active!
INFO:werkzeug: * Debugger PIN: 518-940-869
INFO:xknx.log:XKNX v2.11.2 starting tunneling connection to KNX bus.
INFO:werkzeug:127.0.0.1 - - [20/Feb/2024 11:36:26] "POST /api/readgroup HTTP/1.1" 200 -
INFO:xknx.log:XKNX v2.11.2 starting tunneling connection to KNX bus.
ERROR:xknx.log:Unexpected error while processing outgoing telegram <Telegram direction="Outgoing" source_address="0.0.2" destination_address="0/0/6" payload="<GroupValueRead />" />
Traceback (most recent call last):
  File "/usr/lib/python3.11/site-packages/xknx/core/telegram_queue.py", line 169, in _outgoing_rate_limiter
    await self.process_telegram_outgoing(telegram)
  File "/usr/lib/python3.11/site-packages/xknx/core/telegram_queue.py", line 205, in process_telegram_outgoing
    await self.xknx.cemi_handler.send_telegram(telegram)
  File "/usr/lib/python3.11/site-packages/xknx/cemi/cemi_handler.py", line 82, in send_telegram
    await self._l_data_confirmation_event.wait()
  File "/usr/lib/python3.11/asyncio/locks.py", line 210, in wait
    fut = self._get_loop().create_future()
          ^^^^^^^^^^^^^^^^
  File "/usr/lib/python3.11/asyncio/mixins.py", line 20, in _get_loop
    raise RuntimeError(f'{self!r} is bound to a different event loop')
RuntimeError: <asyncio.locks.Event object at 0x7fa7c2fce990 [unset]> is bound to a different event loop
WARNING:xknx.log:Error: KNX bus did not respond in time (2.0 secs) to GroupValueRead request for: 0/0/6
INFO:werkzeug:127.0.0.1 - - [20/Feb/2024 11:36:29] "[35m[1mPOST /api/readgroup HTTP/1.1[0m" 500 -
INFO:werkzeug: * Detected change in '/home/amenia/Documents/Projekte/pyknx-con/main.py', reloading
INFO:werkzeug: * Restarting with stat
WARNING:werkzeug: * Debugger is active!
INFO:werkzeug: * Debugger PIN: 518-940-869
INFO:werkzeug:[31m[1mWARNING: This is a development server. Do not use it in a production deployment. Use a production WSGI server instead.[0m
 * Running on all addresses (0.0.0.0)
 * Running on http://127.0.0.1:5000
 * Running on http://10.106.67.2:5000
INFO:werkzeug:[33mPress CTRL+C to quit[0m
INFO:werkzeug: * Restarting with stat
WARNING:werkzeug: * Debugger is active!
INFO:werkzeug: * Debugger PIN: 518-940-869
INFO:xknx.log:XKNX v2.11.2 starting tunneling connection to KNX bus.
INFO:werkzeug:127.0.0.1 - - [20/Feb/2024 11:36:51] "POST /api/readgroup HTTP/1.1" 200 -
INFO:xknx.log:XKNX v2.11.2 starting tunneling connection to KNX bus.
ERROR:xknx.log:Unexpected error while processing outgoing telegram <Telegram direction="Outgoing" source_address="0.0.4" destination_address="0/0/6" payload="<GroupValueRead />" />
Traceback (most recent call last):
  File "/usr/lib/python3.11/site-packages/xknx/core/telegram_queue.py", line 169, in _outgoing_rate_limiter
    await self.process_telegram_outgoing(telegram)
  File "/usr/lib/python3.11/site-packages/xknx/core/telegram_queue.py", line 205, in process_telegram_outgoing
    await self.xknx.cemi_handler.send_telegram(telegram)
  File "/usr/lib/python3.11/site-packages/xknx/cemi/cemi_handler.py", line 82, in send_telegram
    await self._l_data_confirmation_event.wait()
  File "/usr/lib/python3.11/asyncio/locks.py", line 210, in wait
    fut = self._get_loop().create_future()
          ^^^^^^^^^^^^^^^^
  File "/usr/lib/python3.11/asyncio/mixins.py", line 20, in _get_loop
    raise RuntimeError(f'{self!r} is bound to a different event loop')
RuntimeError: <asyncio.locks.Event object at 0x77eac39d6b90 [unset]> is bound to a different event loop
WARNING:xknx.log:Error: KNX bus did not respond in time (2.0 secs) to GroupValueRead request for: 0/0/6
INFO:werkzeug:127.0.0.1 - - [20/Feb/2024 11:36:54] "[35m[1mPOST /api/readgroup HTTP/1.1[0m" 500 -
INFO:werkzeug: * Detected change in '/home/amenia/Documents/Projekte/pyknx-con/main.py', reloading
INFO:werkzeug: * Restarting with stat
INFO:werkzeug:[31m[1mWARNING: This is a development server. Do not use it in a production deployment. Use a production WSGI server instead.[0m
 * Running on all addresses (0.0.0.0)
 * Running on http://127.0.0.1:5000
 * Running on http://10.106.67.2:5000
INFO:werkzeug:[33mPress CTRL+C to quit[0m
INFO:werkzeug: * Restarting with stat
WARNING:werkzeug: * Debugger is active!
INFO:werkzeug: * Debugger PIN: 518-940-869
INFO:xknx.log:XKNX v2.11.2 starting tunneling connection to KNX bus.
INFO:werkzeug:127.0.0.1 - - [20/Feb/2024 11:38:53] "POST /api/readgroup HTTP/1.1" 200 -
INFO:xknx.log:XKNX v2.11.2 starting tunneling connection to KNX bus.
ERROR:xknx.log:Unexpected error while processing outgoing telegram <Telegram direction="Outgoing" source_address="0.0.6" destination_address="0/0/6" payload="<GroupValueRead />" />
Traceback (most recent call last):
  File "/usr/lib/python3.11/site-packages/xknx/core/telegram_queue.py", line 169, in _outgoing_rate_limiter
    await self.process_telegram_outgoing(telegram)
  File "/usr/lib/python3.11/site-packages/xknx/core/telegram_queue.py", line 205, in process_telegram_outgoing
    await self.xknx.cemi_handler.send_telegram(telegram)
  File "/usr/lib/python3.11/site-packages/xknx/cemi/cemi_handler.py", line 82, in send_telegram
    await self._l_data_confirmation_event.wait()
  File "/usr/lib/python3.11/asyncio/locks.py", line 210, in wait
    fut = self._get_loop().create_future()
          ^^^^^^^^^^^^^^^^
  File "/usr/lib/python3.11/asyncio/mixins.py", line 20, in _get_loop
    raise RuntimeError(f'{self!r} is bound to a different event loop')
RuntimeError: <asyncio.locks.Event object at 0x7e1d34dee650 [unset]> is bound to a different event loop
WARNING:xknx.log:Error: KNX bus did not respond in time (2.0 secs) to GroupValueRead request for: 0/0/6
INFO:werkzeug:127.0.0.1 - - [20/Feb/2024 11:38:57] "[35m[1mPOST /api/readgroup HTTP/1.1[0m" 500 -
INFO:werkzeug: * Detected change in '/home/amenia/Documents/Projekte/pyknx-con/main.py', reloading
INFO:werkzeug: * Restarting with stat
WARNING:werkzeug: * Debugger is active!
INFO:werkzeug: * Debugger PIN: 518-940-869
INFO:werkzeug:[31m[1mWARNING: This is a development server. Do not use it in a production deployment. Use a production WSGI server instead.[0m
 * Running on all addresses (0.0.0.0)
 * Running on http://127.0.0.1:5000
 * Running on http://10.106.67.2:5000
INFO:werkzeug:[33mPress CTRL+C to quit[0m
INFO:werkzeug: * Restarting with stat
WARNING:werkzeug: * Debugger is active!
INFO:werkzeug: * Debugger PIN: 518-940-869
INFO:xknx.log:XKNX v2.11.2 starting tunneling connection to KNX bus.
INFO:werkzeug:127.0.0.1 - - [20/Feb/2024 11:41:24] "POST /api/readgroup HTTP/1.1" 200 -
INFO:xknx.log:XKNX v2.11.2 starting tunneling connection to KNX bus.
ERROR:xknx.log:Unexpected error while processing outgoing telegram <Telegram direction="Outgoing" source_address="0.0.8" destination_address="0/0/6" payload="<GroupValueRead />" />
Traceback (most recent call last):
  File "/usr/lib/python3.11/site-packages/xknx/core/telegram_queue.py", line 169, in _outgoing_rate_limiter
    await self.process_telegram_outgoing(telegram)
  File "/usr/lib/python3.11/site-packages/xknx/core/telegram_queue.py", line 205, in process_telegram_outgoing
    await self.xknx.cemi_handler.send_telegram(telegram)
  File "/usr/lib/python3.11/site-packages/xknx/cemi/cemi_handler.py", line 82, in send_telegram
    await self._l_data_confirmation_event.wait()
  File "/usr/lib/python3.11/asyncio/locks.py", line 210, in wait
    fut = self._get_loop().create_future()
          ^^^^^^^^^^^^^^^^
  File "/usr/lib/python3.11/asyncio/mixins.py", line 20, in _get_loop
    raise RuntimeError(f'{self!r} is bound to a different event loop')
RuntimeError: <asyncio.locks.Event object at 0x73c4f67ce890 [unset]> is bound to a different event loop
WARNING:xknx.log:Error: KNX bus did not respond in time (2.0 secs) to GroupValueRead request for: 0/0/6
INFO:werkzeug:127.0.0.1 - - [20/Feb/2024 11:41:27] "[35m[1mPOST /api/readgroup HTTP/1.1[0m" 500 -
INFO:werkzeug: * Detected change in '/home/amenia/Documents/Projekte/pyknx-con/main.py', reloading
INFO:werkzeug: * Restarting with stat
WARNING:werkzeug: * Debugger is active!
INFO:werkzeug: * Debugger PIN: 518-940-869
INFO:werkzeug:[31m[1mWARNING: This is a development server. Do not use it in a production deployment. Use a production WSGI server instead.[0m
 * Running on all addresses (0.0.0.0)
 * Running on http://127.0.0.1:5000
 * Running on http://10.106.67.2:5000
INFO:werkzeug:[33mPress CTRL+C to quit[0m
INFO:werkzeug: * Restarting with stat
WARNING:werkzeug: * Debugger is active!
INFO:werkzeug: * Debugger PIN: 518-940-869
INFO:xknx.log:XKNX v2.11.2 starting tunneling connection to KNX bus.
INFO:werkzeug:127.0.0.1 - - [20/Feb/2024 11:43:14] "POST /api/readgroup HTTP/1.1" 200 -
INFO:xknx.log:XKNX v2.11.2 starting tunneling connection to KNX bus.
ERROR:xknx.log:Unexpected error while processing outgoing telegram <Telegram direction="Outgoing" source_address="0.0.2" destination_address="0/0/6" payload="<GroupValueRead />" />
Traceback (most recent call last):
  File "/usr/lib/python3.11/site-packages/xknx/core/telegram_queue.py", line 169, in _outgoing_rate_limiter
    await self.process_telegram_outgoing(telegram)
  File "/usr/lib/python3.11/site-packages/xknx/core/telegram_queue.py", line 205, in process_telegram_outgoing
    await self.xknx.cemi_handler.send_telegram(telegram)
  File "/usr/lib/python3.11/site-packages/xknx/cemi/cemi_handler.py", line 82, in send_telegram
    await self._l_data_confirmation_event.wait()
  File "/usr/lib/python3.11/asyncio/locks.py", line 210, in wait
    fut = self._get_loop().create_future()
          ^^^^^^^^^^^^^^^^
  File "/usr/lib/python3.11/asyncio/mixins.py", line 20, in _get_loop
    raise RuntimeError(f'{self!r} is bound to a different event loop')
RuntimeError: <asyncio.locks.Event object at 0x7bdd2a6f2ad0 [unset]> is bound to a different event loop
WARNING:xknx.log:Error: KNX bus did not respond in time (2.0 secs) to GroupValueRead request for: 0/0/6
INFO:werkzeug:127.0.0.1 - - [20/Feb/2024 11:43:17] "[35m[1mPOST /api/readgroup HTTP/1.1[0m" 500 -
INFO:xknx.log:XKNX v2.11.2 starting tunneling connection to KNX bus.
ERROR:asyncio:_GatheringFuture exception was never retrieved
future: <_GatheringFuture finished exception=RuntimeError('<Queue at 0x7bdd2a6f2950 maxsize=0 tasks=1> is bound to a different event loop')>
Traceback (most recent call last):
  File "/usr/lib/python3.11/site-packages/xknx/core/telegram_queue.py", line 119, in _telegram_consumer
    telegram = await self.xknx.telegrams.get()
               ^^^^^^^^^^^^^^^^^^^^^^^^^^^^^^^
  File "/usr/lib/python3.11/asyncio/queues.py", line 155, in get
    getter = self._get_loop().create_future()
             ^^^^^^^^^^^^^^^^
  File "/usr/lib/python3.11/asyncio/mixins.py", line 20, in _get_loop
    raise RuntimeError(f'{self!r} is bound to a different event loop')
RuntimeError: <Queue at 0x7bdd2a6f2950 maxsize=0 tasks=1> is bound to a different event loop
INFO:werkzeug:127.0.0.1 - - [20/Feb/2024 11:43:18] "[35m[1mPOST /api/readgroup HTTP/1.1[0m" 500 -
INFO:xknx.log:XKNX v2.11.2 starting tunneling connection to KNX bus.
ERROR:asyncio:_GatheringFuture exception was never retrieved
future: <_GatheringFuture finished exception=RuntimeError('<Queue at 0x7bdd2a6f2a10 maxsize=0> is bound to a different event loop')>
Traceback (most recent call last):
  File "/usr/lib/python3.11/site-packages/xknx/core/telegram_queue.py", line 150, in _outgoing_rate_limiter
    telegram = await self.outgoing_queue.get()
               ^^^^^^^^^^^^^^^^^^^^^^^^^^^^^^^
  File "/usr/lib/python3.11/asyncio/queues.py", line 155, in get
    getter = self._get_loop().create_future()
             ^^^^^^^^^^^^^^^^
  File "/usr/lib/python3.11/asyncio/mixins.py", line 20, in _get_loop
    raise RuntimeError(f'{self!r} is bound to a different event loop')
RuntimeError: <Queue at 0x7bdd2a6f2a10 maxsize=0> is bound to a different event loop
ERROR:xknx.log:Unexpected error while processing outgoing telegram <Telegram direction="Outgoing" source_address="0.0.3" destination_address="0/0/6" payload="<GroupValueRead />" />
Traceback (most recent call last):
  File "/usr/lib/python3.11/site-packages/xknx/core/telegram_queue.py", line 169, in _outgoing_rate_limiter
    await self.process_telegram_outgoing(telegram)
  File "/usr/lib/python3.11/site-packages/xknx/core/telegram_queue.py", line 205, in process_telegram_outgoing
    await self.xknx.cemi_handler.send_telegram(telegram)
  File "/usr/lib/python3.11/site-packages/xknx/cemi/cemi_handler.py", line 82, in send_telegram
    await self._l_data_confirmation_event.wait()
  File "/usr/lib/python3.11/asyncio/locks.py", line 210, in wait
    fut = self._get_loop().create_future()
          ^^^^^^^^^^^^^^^^
  File "/usr/lib/python3.11/asyncio/mixins.py", line 20, in _get_loop
    raise RuntimeError(f'{self!r} is bound to a different event loop')
RuntimeError: <asyncio.locks.Event object at 0x7bdd2a6f2ad0 [unset]> is bound to a different event loop
WARNING:xknx.log:Error: KNX bus did not respond in time (2.0 secs) to GroupValueRead request for: 0/0/6
INFO:werkzeug:127.0.0.1 - - [20/Feb/2024 11:43:21] "[35m[1mPOST /api/readgroup HTTP/1.1[0m" 500 -
INFO:xknx.log:XKNX v2.11.2 starting tunneling connection to KNX bus.
ERROR:asyncio:_GatheringFuture exception was never retrieved
future: <_GatheringFuture finished exception=RuntimeError('<Queue at 0x7bdd2a6f2950 maxsize=0 tasks=2> is bound to a different event loop')>
Traceback (most recent call last):
  File "/usr/lib/python3.11/site-packages/xknx/core/telegram_queue.py", line 119, in _telegram_consumer
    telegram = await self.xknx.telegrams.get()
               ^^^^^^^^^^^^^^^^^^^^^^^^^^^^^^^
  File "/usr/lib/python3.11/asyncio/queues.py", line 155, in get
    getter = self._get_loop().create_future()
             ^^^^^^^^^^^^^^^^
  File "/usr/lib/python3.11/asyncio/mixins.py", line 20, in _get_loop
    raise RuntimeError(f'{self!r} is bound to a different event loop')
RuntimeError: <Queue at 0x7bdd2a6f2950 maxsize=0 tasks=2> is bound to a different event loop
INFO:werkzeug:127.0.0.1 - - [20/Feb/2024 11:43:23] "[35m[1mPOST /api/readgroup HTTP/1.1[0m" 500 -
INFO:xknx.log:XKNX v2.11.2 starting tunneling connection to KNX bus.
ERROR:asyncio:_GatheringFuture exception was never retrieved
future: <_GatheringFuture finished exception=RuntimeError('<Queue at 0x7bdd2a6f2a10 maxsize=0> is bound to a different event loop')>
Traceback (most recent call last):
  File "/usr/lib/python3.11/site-packages/xknx/core/telegram_queue.py", line 150, in _outgoing_rate_limiter
    telegram = await self.outgoing_queue.get()
               ^^^^^^^^^^^^^^^^^^^^^^^^^^^^^^^
  File "/usr/lib/python3.11/asyncio/queues.py", line 155, in get
    getter = self._get_loop().create_future()
             ^^^^^^^^^^^^^^^^
  File "/usr/lib/python3.11/asyncio/mixins.py", line 20, in _get_loop
    raise RuntimeError(f'{self!r} is bound to a different event loop')
RuntimeError: <Queue at 0x7bdd2a6f2a10 maxsize=0> is bound to a different event loop
ERROR:xknx.log:Unexpected error while processing outgoing telegram <Telegram direction="Outgoing" source_address="0.0.5" destination_address="0/0/6" payload="<GroupValueRead />" />
Traceback (most recent call last):
  File "/usr/lib/python3.11/site-packages/xknx/core/telegram_queue.py", line 169, in _outgoing_rate_limiter
    await self.process_telegram_outgoing(telegram)
  File "/usr/lib/python3.11/site-packages/xknx/core/telegram_queue.py", line 205, in process_telegram_outgoing
    await self.xknx.cemi_handler.send_telegram(telegram)
  File "/usr/lib/python3.11/site-packages/xknx/cemi/cemi_handler.py", line 82, in send_telegram
    await self._l_data_confirmation_event.wait()
  File "/usr/lib/python3.11/asyncio/locks.py", line 210, in wait
    fut = self._get_loop().create_future()
          ^^^^^^^^^^^^^^^^
  File "/usr/lib/python3.11/asyncio/mixins.py", line 20, in _get_loop
    raise RuntimeError(f'{self!r} is bound to a different event loop')
RuntimeError: <asyncio.locks.Event object at 0x7bdd2a6f2ad0 [unset]> is bound to a different event loop
WARNING:xknx.log:Error: KNX bus did not respond in time (2.0 secs) to GroupValueRead request for: 0/0/6
INFO:werkzeug:127.0.0.1 - - [20/Feb/2024 11:43:26] "[35m[1mPOST /api/readgroup HTTP/1.1[0m" 500 -
INFO:werkzeug: * Detected change in '/home/amenia/Documents/Projekte/pyknx-con/main.py', reloading
INFO:werkzeug: * Restarting with stat
WARNING:werkzeug: * Debugger is active!
INFO:werkzeug: * Debugger PIN: 518-940-869
INFO:werkzeug:[31m[1mWARNING: This is a development server. Do not use it in a production deployment. Use a production WSGI server instead.[0m
 * Running on all addresses (0.0.0.0)
 * Running on http://127.0.0.1:5000
 * Running on http://10.106.67.2:5000
INFO:werkzeug:[33mPress CTRL+C to quit[0m
INFO:werkzeug: * Restarting with stat
WARNING:werkzeug: * Debugger is active!
INFO:werkzeug: * Debugger PIN: 518-940-869
INFO:xknx.log:XKNX v2.11.2 starting tunneling connection to KNX bus.
INFO:werkzeug:127.0.0.1 - - [20/Feb/2024 11:44:39] "POST /api/readgroup HTTP/1.1" 200 -
INFO:xknx.log:XKNX v2.11.2 starting tunneling connection to KNX bus.
ERROR:xknx.log:Unexpected error while processing outgoing telegram <Telegram direction="Outgoing" source_address="0.0.8" destination_address="0/0/6" payload="<GroupValueRead />" />
Traceback (most recent call last):
  File "/usr/lib/python3.11/site-packages/xknx/core/telegram_queue.py", line 169, in _outgoing_rate_limiter
    await self.process_telegram_outgoing(telegram)
  File "/usr/lib/python3.11/site-packages/xknx/core/telegram_queue.py", line 205, in process_telegram_outgoing
    await self.xknx.cemi_handler.send_telegram(telegram)
  File "/usr/lib/python3.11/site-packages/xknx/cemi/cemi_handler.py", line 82, in send_telegram
    await self._l_data_confirmation_event.wait()
  File "/usr/lib/python3.11/asyncio/locks.py", line 210, in wait
    fut = self._get_loop().create_future()
          ^^^^^^^^^^^^^^^^
  File "/usr/lib/python3.11/asyncio/mixins.py", line 20, in _get_loop
    raise RuntimeError(f'{self!r} is bound to a different event loop')
RuntimeError: <asyncio.locks.Event object at 0x7356a96d6710 [unset]> is bound to a different event loop
WARNING:xknx.log:Error: KNX bus did not respond in time (2.0 secs) to GroupValueRead request for: 0/0/6
INFO:werkzeug:127.0.0.1 - - [20/Feb/2024 11:44:43] "[35m[1mPOST /api/readgroup HTTP/1.1[0m" 500 -
INFO:werkzeug: * Detected change in '/home/amenia/Documents/Projekte/pyknx-con/main.py', reloading
INFO:werkzeug: * Restarting with stat
WARNING:werkzeug: * Debugger is active!
INFO:werkzeug: * Debugger PIN: 518-940-869
INFO:werkzeug: * Detected change in '/home/amenia/Documents/Projekte/pyknx-con/main.py', reloading
INFO:werkzeug: * Restarting with stat
WARNING:werkzeug: * Debugger is active!
INFO:werkzeug: * Debugger PIN: 518-940-869
INFO:werkzeug:[31m[1mWARNING: This is a development server. Do not use it in a production deployment. Use a production WSGI server instead.[0m
 * Running on all addresses (0.0.0.0)
 * Running on http://127.0.0.1:5000
 * Running on http://10.106.67.2:5000
INFO:werkzeug:[33mPress CTRL+C to quit[0m
INFO:werkzeug: * Restarting with stat
WARNING:werkzeug: * Debugger is active!
INFO:werkzeug: * Debugger PIN: 518-940-869
INFO:xknx.log:XKNX v2.11.2 starting tunneling connection to KNX bus.
INFO:werkzeug:127.0.0.1 - - [20/Feb/2024 11:46:14] "POST /api/readgroup HTTP/1.1" 200 -
INFO:xknx.log:XKNX v2.11.2 starting tunneling connection to KNX bus.
ERROR:xknx.log:Unexpected error while processing outgoing telegram <Telegram direction="Outgoing" source_address="0.0.2" destination_address="0/0/6" payload="<GroupValueRead />" />
Traceback (most recent call last):
  File "/usr/lib/python3.11/site-packages/xknx/core/telegram_queue.py", line 169, in _outgoing_rate_limiter
    await self.process_telegram_outgoing(telegram)
  File "/usr/lib/python3.11/site-packages/xknx/core/telegram_queue.py", line 205, in process_telegram_outgoing
    await self.xknx.cemi_handler.send_telegram(telegram)
  File "/usr/lib/python3.11/site-packages/xknx/cemi/cemi_handler.py", line 82, in send_telegram
    await self._l_data_confirmation_event.wait()
  File "/usr/lib/python3.11/asyncio/locks.py", line 210, in wait
    fut = self._get_loop().create_future()
          ^^^^^^^^^^^^^^^^
  File "/usr/lib/python3.11/asyncio/mixins.py", line 20, in _get_loop
    raise RuntimeError(f'{self!r} is bound to a different event loop')
RuntimeError: <asyncio.locks.Event object at 0x7b93a02f2790 [unset]> is bound to a different event loop
WARNING:xknx.log:Error: KNX bus did not respond in time (2.0 secs) to GroupValueRead request for: 0/0/6
INFO:werkzeug:127.0.0.1 - - [20/Feb/2024 11:46:17] "[35m[1mPOST /api/readgroup HTTP/1.1[0m" 500 -
INFO:werkzeug: * Detected change in '/home/amenia/Documents/Projekte/pyknx-con/main.py', reloading
INFO:werkzeug: * Restarting with stat
WARNING:werkzeug: * Debugger is active!
INFO:werkzeug: * Debugger PIN: 518-940-869
INFO:werkzeug:[31m[1mWARNING: This is a development server. Do not use it in a production deployment. Use a production WSGI server instead.[0m
 * Running on all addresses (0.0.0.0)
 * Running on http://127.0.0.1:5000
 * Running on http://10.106.67.2:5000
INFO:werkzeug:[33mPress CTRL+C to quit[0m
INFO:werkzeug: * Restarting with stat
WARNING:werkzeug: * Debugger is active!
INFO:werkzeug: * Debugger PIN: 518-940-869
INFO:xknx.log:XKNX v2.11.2 starting tunneling connection to KNX bus.
INFO:werkzeug:127.0.0.1 - - [20/Feb/2024 11:48:01] "POST /api/readgroup HTTP/1.1" 200 -
INFO:xknx.log:XKNX v2.11.2 starting tunneling connection to KNX bus.
ERROR:xknx.log:Unexpected error while processing outgoing telegram <Telegram direction="Outgoing" source_address="0.0.4" destination_address="0/0/6" payload="<GroupValueRead />" />
Traceback (most recent call last):
  File "/usr/lib/python3.11/site-packages/xknx/core/telegram_queue.py", line 169, in _outgoing_rate_limiter
    await self.process_telegram_outgoing(telegram)
  File "/usr/lib/python3.11/site-packages/xknx/core/telegram_queue.py", line 205, in process_telegram_outgoing
    await self.xknx.cemi_handler.send_telegram(telegram)
  File "/usr/lib/python3.11/site-packages/xknx/cemi/cemi_handler.py", line 82, in send_telegram
    await self._l_data_confirmation_event.wait()
  File "/usr/lib/python3.11/asyncio/locks.py", line 210, in wait
    fut = self._get_loop().create_future()
          ^^^^^^^^^^^^^^^^
  File "/usr/lib/python3.11/asyncio/mixins.py", line 20, in _get_loop
    raise RuntimeError(f'{self!r} is bound to a different event loop')
RuntimeError: <asyncio.locks.Event object at 0x7972ca2d6690 [unset]> is bound to a different event loop
WARNING:xknx.log:Error: KNX bus did not respond in time (2.0 secs) to GroupValueRead request for: 0/0/6
INFO:werkzeug:127.0.0.1 - - [20/Feb/2024 11:48:04] "[35m[1mPOST /api/readgroup HTTP/1.1[0m" 500 -
INFO:werkzeug: * Detected change in '/home/amenia/Documents/Projekte/pyknx-con/main.py', reloading
INFO:werkzeug: * Restarting with stat
INFO:werkzeug:[31m[1mWARNING: This is a development server. Do not use it in a production deployment. Use a production WSGI server instead.[0m
 * Running on all addresses (0.0.0.0)
 * Running on http://127.0.0.1:5000
 * Running on http://10.106.67.2:5000
INFO:werkzeug:[33mPress CTRL+C to quit[0m
INFO:werkzeug: * Restarting with stat
WARNING:werkzeug: * Debugger is active!
INFO:werkzeug: * Debugger PIN: 518-940-869
INFO:werkzeug:127.0.0.1 - - [20/Feb/2024 11:49:34] "[35m[1mPOST /api/readgroup HTTP/1.1[0m" 500 -
INFO:werkzeug:127.0.0.1 - - [20/Feb/2024 11:49:39] "[35m[1mPOST /api/readgroup HTTP/1.1[0m" 500 -
INFO:werkzeug: * Detected change in '/home/amenia/Documents/Projekte/pyknx-con/main.py', reloading
INFO:werkzeug: * Restarting with stat
INFO:werkzeug:[31m[1mWARNING: This is a development server. Do not use it in a production deployment. Use a production WSGI server instead.[0m
 * Running on all addresses (0.0.0.0)
 * Running on http://127.0.0.1:5000
 * Running on http://10.106.67.2:5000
INFO:werkzeug:[33mPress CTRL+C to quit[0m
INFO:werkzeug: * Restarting with stat
WARNING:werkzeug: * Debugger is active!
INFO:werkzeug: * Debugger PIN: 518-940-869
INFO:xknx.log:XKNX v2.11.2 starting tunneling connection to KNX bus.
INFO:werkzeug:127.0.0.1 - - [20/Feb/2024 11:50:10] "POST /api/readgroup HTTP/1.1" 200 -
INFO:xknx.log:XKNX v2.11.2 starting tunneling connection to KNX bus.
ERROR:xknx.log:Unexpected error while processing outgoing telegram <Telegram direction="Outgoing" source_address="0.0.6" destination_address="0/0/6" payload="<GroupValueRead />" />
Traceback (most recent call last):
  File "/usr/lib/python3.11/site-packages/xknx/core/telegram_queue.py", line 169, in _outgoing_rate_limiter
    await self.process_telegram_outgoing(telegram)
  File "/usr/lib/python3.11/site-packages/xknx/core/telegram_queue.py", line 205, in process_telegram_outgoing
    await self.xknx.cemi_handler.send_telegram(telegram)
  File "/usr/lib/python3.11/site-packages/xknx/cemi/cemi_handler.py", line 82, in send_telegram
    await self._l_data_confirmation_event.wait()
  File "/usr/lib/python3.11/asyncio/locks.py", line 210, in wait
    fut = self._get_loop().create_future()
          ^^^^^^^^^^^^^^^^
  File "/usr/lib/python3.11/asyncio/mixins.py", line 20, in _get_loop
    raise RuntimeError(f'{self!r} is bound to a different event loop')
RuntimeError: <asyncio.locks.Event object at 0x707e5d4d6890 [unset]> is bound to a different event loop
WARNING:xknx.log:Error: KNX bus did not respond in time (2.0 secs) to GroupValueRead request for: 0/0/6
INFO:werkzeug:127.0.0.1 - - [20/Feb/2024 11:50:14] "[35m[1mPOST /api/readgroup HTTP/1.1[0m" 500 -
INFO:werkzeug: * Detected change in '/home/amenia/Documents/Projekte/pyknx-con/main.py', reloading
INFO:werkzeug: * Restarting with stat
WARNING:werkzeug: * Debugger is active!
INFO:werkzeug: * Debugger PIN: 518-940-869
INFO:xknx.log:XKNX v2.11.2 starting tunneling connection to KNX bus.
INFO:werkzeug:127.0.0.1 - - [20/Feb/2024 11:51:10] "[35m[1mPOST /api/readgroup HTTP/1.1[0m" 500 -
INFO:xknx.log:XKNX v2.11.2 starting tunneling connection to KNX bus.
INFO:werkzeug:127.0.0.1 - - [20/Feb/2024 11:51:12] "[35m[1mPOST /api/readgroup HTTP/1.1[0m" 500 -
INFO:xknx.log:XKNX v2.11.2 starting tunneling connection to KNX bus.
INFO:werkzeug:[31m[1mWARNING: This is a development server. Do not use it in a production deployment. Use a production WSGI server instead.[0m
 * Running on all addresses (0.0.0.0)
 * Running on http://127.0.0.1:5000
 * Running on http://10.106.67.2:5000
INFO:werkzeug:[33mPress CTRL+C to quit[0m
INFO:werkzeug: * Restarting with stat
WARNING:werkzeug: * Debugger is active!
INFO:werkzeug: * Debugger PIN: 518-940-869
INFO:xknx.log:XKNX v2.11.2 starting tunneling connection to KNX bus.
INFO:werkzeug:127.0.0.1 - - [20/Feb/2024 11:51:19] "[35m[1mPOST /api/readgroup HTTP/1.1[0m" 500 -
INFO:werkzeug: * Detected change in '/home/amenia/Documents/Projekte/pyknx-con/main.py', reloading
INFO:werkzeug: * Restarting with stat
WARNING:werkzeug: * Debugger is active!
INFO:werkzeug: * Debugger PIN: 518-940-869
INFO:werkzeug:[31m[1mWARNING: This is a development server. Do not use it in a production deployment. Use a production WSGI server instead.[0m
 * Running on all addresses (0.0.0.0)
 * Running on http://127.0.0.1:5000
 * Running on http://10.106.67.2:5000
INFO:werkzeug:[33mPress CTRL+C to quit[0m
INFO:werkzeug: * Restarting with stat
WARNING:werkzeug: * Debugger is active!
INFO:werkzeug: * Debugger PIN: 518-940-869
INFO:xknx.log:XKNX v2.11.2 starting tunneling connection to KNX bus.
INFO:werkzeug:127.0.0.1 - - [20/Feb/2024 11:51:32] "POST /api/readgroup HTTP/1.1" 200 -
INFO:werkzeug: * Detected change in '/home/amenia/Documents/Projekte/pyknx-con/main.py', reloading
INFO:werkzeug: * Restarting with stat
WARNING:werkzeug: * Debugger is active!
INFO:werkzeug: * Debugger PIN: 518-940-869
INFO:xknx.log:XKNX v2.11.2 starting tunneling connection to KNX bus.
INFO:werkzeug:127.0.0.1 - - [20/Feb/2024 11:52:26] "POST /api/readgroup HTTP/1.1" 200 -
INFO:xknx.log:XKNX v2.11.2 starting tunneling connection to KNX bus.
ERROR:xknx.log:Unexpected error while processing outgoing telegram <Telegram direction="Outgoing" source_address="0.0.5" destination_address="0/0/6" payload="<GroupValueRead />" />
Traceback (most recent call last):
  File "/usr/lib/python3.11/site-packages/xknx/core/telegram_queue.py", line 169, in _outgoing_rate_limiter
    await self.process_telegram_outgoing(telegram)
  File "/usr/lib/python3.11/site-packages/xknx/core/telegram_queue.py", line 205, in process_telegram_outgoing
    await self.xknx.cemi_handler.send_telegram(telegram)
  File "/usr/lib/python3.11/site-packages/xknx/cemi/cemi_handler.py", line 82, in send_telegram
    await self._l_data_confirmation_event.wait()
  File "/usr/lib/python3.11/asyncio/locks.py", line 210, in wait
    fut = self._get_loop().create_future()
          ^^^^^^^^^^^^^^^^
  File "/usr/lib/python3.11/asyncio/mixins.py", line 20, in _get_loop
    raise RuntimeError(f'{self!r} is bound to a different event loop')
RuntimeError: <asyncio.locks.Event object at 0x779d605ee690 [unset]> is bound to a different event loop
WARNING:xknx.log:Error: KNX bus did not respond in time (2.0 secs) to GroupValueRead request for: 0/0/6
INFO:werkzeug:127.0.0.1 - - [20/Feb/2024 11:52:29] "[35m[1mPOST /api/readgroup HTTP/1.1[0m" 500 -
INFO:werkzeug: * Detected change in '/home/amenia/Documents/Projekte/pyknx-con/main.py', reloading
INFO:werkzeug: * Restarting with stat
WARNING:werkzeug: * Debugger is active!
INFO:werkzeug: * Debugger PIN: 518-940-869
INFO:werkzeug: * Detected change in '/home/amenia/Documents/Projekte/pyknx-con/main.py', reloading
INFO:werkzeug: * Restarting with stat
WARNING:werkzeug: * Debugger is active!
INFO:werkzeug: * Debugger PIN: 518-940-869
INFO:xknx.log:XKNX v2.11.2 starting tunneling connection to KNX bus.
INFO:werkzeug:127.0.0.1 - - [20/Feb/2024 11:53:16] "POST /api/readgroup HTTP/1.1" 200 -
INFO:xknx.log:XKNX v2.11.2 starting tunneling connection to KNX bus.
ERROR:xknx.log:Unexpected error while processing outgoing telegram <Telegram direction="Outgoing" source_address="0.0.7" destination_address="0/0/6" payload="<GroupValueRead />" />
Traceback (most recent call last):
  File "/usr/lib/python3.11/site-packages/xknx/core/telegram_queue.py", line 169, in _outgoing_rate_limiter
    await self.process_telegram_outgoing(telegram)
  File "/usr/lib/python3.11/site-packages/xknx/core/telegram_queue.py", line 205, in process_telegram_outgoing
    await self.xknx.cemi_handler.send_telegram(telegram)
  File "/usr/lib/python3.11/site-packages/xknx/cemi/cemi_handler.py", line 82, in send_telegram
    await self._l_data_confirmation_event.wait()
  File "/usr/lib/python3.11/asyncio/locks.py", line 210, in wait
    fut = self._get_loop().create_future()
          ^^^^^^^^^^^^^^^^
  File "/usr/lib/python3.11/asyncio/mixins.py", line 20, in _get_loop
    raise RuntimeError(f'{self!r} is bound to a different event loop')
RuntimeError: <asyncio.locks.Event object at 0x7e37b7ed68d0 [unset]> is bound to a different event loop
WARNING:xknx.log:Error: KNX bus did not respond in time (2.0 secs) to GroupValueRead request for: 0/0/6
INFO:werkzeug:127.0.0.1 - - [20/Feb/2024 11:53:20] "[35m[1mPOST /api/readgroup HTTP/1.1[0m" 500 -
INFO:xknx.log:XKNX v2.11.2 starting tunneling connection to KNX bus.
ERROR:asyncio:_GatheringFuture exception was never retrieved
future: <_GatheringFuture finished exception=RuntimeError('<Queue at 0x7e37b7ed6750 maxsize=0 tasks=1> is bound to a different event loop')>
Traceback (most recent call last):
  File "/usr/lib/python3.11/site-packages/xknx/core/telegram_queue.py", line 119, in _telegram_consumer
    telegram = await self.xknx.telegrams.get()
               ^^^^^^^^^^^^^^^^^^^^^^^^^^^^^^^
  File "/usr/lib/python3.11/asyncio/queues.py", line 155, in get
    getter = self._get_loop().create_future()
             ^^^^^^^^^^^^^^^^
  File "/usr/lib/python3.11/asyncio/mixins.py", line 20, in _get_loop
    raise RuntimeError(f'{self!r} is bound to a different event loop')
RuntimeError: <Queue at 0x7e37b7ed6750 maxsize=0 tasks=1> is bound to a different event loop
INFO:werkzeug:127.0.0.1 - - [20/Feb/2024 11:53:21] "[35m[1mPOST /api/readgroup HTTP/1.1[0m" 500 -
INFO:werkzeug: * Detected change in '/home/amenia/Documents/Projekte/pyknx-con/main.py', reloading
INFO:werkzeug: * Restarting with stat
WARNING:werkzeug: * Debugger is active!
INFO:werkzeug: * Debugger PIN: 518-940-869
INFO:werkzeug:[31m[1mWARNING: This is a development server. Do not use it in a production deployment. Use a production WSGI server instead.[0m
 * Running on all addresses (0.0.0.0)
 * Running on http://127.0.0.1:5000
 * Running on http://10.106.67.2:5000
INFO:werkzeug:[33mPress CTRL+C to quit[0m
INFO:werkzeug: * Restarting with stat
WARNING:werkzeug: * Debugger is active!
INFO:werkzeug: * Debugger PIN: 518-940-869
INFO:xknx.log:XKNX v2.11.2 starting tunneling connection to KNX bus.
INFO:werkzeug:127.0.0.1 - - [20/Feb/2024 11:54:50] "POST /api/readgroup HTTP/1.1" 200 -
INFO:xknx.log:XKNX v2.11.2 starting tunneling connection to KNX bus.
ERROR:xknx.log:Unexpected error while processing outgoing telegram <Telegram direction="Outgoing" source_address="0.0.2" destination_address="0/0/6" payload="<GroupValueRead />" />
Traceback (most recent call last):
  File "/usr/lib/python3.11/site-packages/xknx/core/telegram_queue.py", line 169, in _outgoing_rate_limiter
    await self.process_telegram_outgoing(telegram)
  File "/usr/lib/python3.11/site-packages/xknx/core/telegram_queue.py", line 205, in process_telegram_outgoing
    await self.xknx.cemi_handler.send_telegram(telegram)
  File "/usr/lib/python3.11/site-packages/xknx/cemi/cemi_handler.py", line 82, in send_telegram
    await self._l_data_confirmation_event.wait()
  File "/usr/lib/python3.11/asyncio/locks.py", line 210, in wait
    fut = self._get_loop().create_future()
          ^^^^^^^^^^^^^^^^
  File "/usr/lib/python3.11/asyncio/mixins.py", line 20, in _get_loop
    raise RuntimeError(f'{self!r} is bound to a different event loop')
RuntimeError: <asyncio.locks.Event object at 0x70ef1ecd6b10 [unset]> is bound to a different event loop
WARNING:xknx.log:Error: KNX bus did not respond in time (2.0 secs) to GroupValueRead request for: 0/0/6
INFO:werkzeug:127.0.0.1 - - [20/Feb/2024 11:54:53] "[35m[1mPOST /api/readgroup HTTP/1.1[0m" 500 -
INFO:werkzeug: * Detected change in '/home/amenia/Documents/Projekte/pyknx-con/main.py', reloading
INFO:werkzeug: * Restarting with stat
WARNING:werkzeug: * Debugger is active!
INFO:werkzeug: * Debugger PIN: 518-940-869
INFO:werkzeug:[31m[1mWARNING: This is a development server. Do not use it in a production deployment. Use a production WSGI server instead.[0m
 * Running on all addresses (0.0.0.0)
 * Running on http://127.0.0.1:5000
 * Running on http://10.106.67.2:5000
INFO:werkzeug:[33mPress CTRL+C to quit[0m
INFO:werkzeug: * Restarting with stat
WARNING:werkzeug: * Debugger is active!
INFO:werkzeug: * Debugger PIN: 518-940-869
INFO:werkzeug:127.0.0.1 - - [20/Feb/2024 11:55:35] "[35m[1mPOST /api/readgroup HTTP/1.1[0m" 500 -
INFO:werkzeug:127.0.0.1 - - [20/Feb/2024 11:55:36] "[35m[1mPOST /api/readgroup HTTP/1.1[0m" 500 -
INFO:werkzeug: * Detected change in '/home/amenia/Documents/Projekte/pyknx-con/main.py', reloading
INFO:werkzeug: * Restarting with stat
WARNING:werkzeug: * Debugger is active!
INFO:werkzeug: * Debugger PIN: 518-940-869
INFO:xknx.log:XKNX v2.11.2 starting tunneling connection to KNX bus.
INFO:werkzeug:127.0.0.1 - - [20/Feb/2024 11:55:44] "POST /api/readgroup HTTP/1.1" 200 -
INFO:xknx.log:XKNX v2.11.2 starting tunneling connection to KNX bus.
ERROR:xknx.log:Unexpected error while processing outgoing telegram <Telegram direction="Outgoing" source_address="0.0.4" destination_address="0/0/6" payload="<GroupValueRead />" />
Traceback (most recent call last):
  File "/usr/lib/python3.11/site-packages/xknx/core/telegram_queue.py", line 169, in _outgoing_rate_limiter
    await self.process_telegram_outgoing(telegram)
  File "/usr/lib/python3.11/site-packages/xknx/core/telegram_queue.py", line 205, in process_telegram_outgoing
    await self.xknx.cemi_handler.send_telegram(telegram)
  File "/usr/lib/python3.11/site-packages/xknx/cemi/cemi_handler.py", line 82, in send_telegram
    await self._l_data_confirmation_event.wait()
  File "/usr/lib/python3.11/asyncio/locks.py", line 210, in wait
    fut = self._get_loop().create_future()
          ^^^^^^^^^^^^^^^^
  File "/usr/lib/python3.11/asyncio/mixins.py", line 20, in _get_loop
    raise RuntimeError(f'{self!r} is bound to a different event loop')
RuntimeError: <asyncio.locks.Event object at 0x7fec8d5cea90 [unset]> is bound to a different event loop
WARNING:xknx.log:Error: KNX bus did not respond in time (2.0 secs) to GroupValueRead request for: 0/0/6
INFO:werkzeug:127.0.0.1 - - [20/Feb/2024 11:55:47] "[35m[1mPOST /api/readgroup HTTP/1.1[0m" 500 -
INFO:werkzeug: * Detected change in '/home/amenia/Documents/Projekte/pyknx-con/main.py', reloading
INFO:werkzeug: * Restarting with stat
WARNING:werkzeug: * Debugger is active!
INFO:werkzeug: * Debugger PIN: 518-940-869
INFO:werkzeug: * Detected change in '/home/amenia/Documents/Projekte/pyknx-con/main.py', reloading
INFO:werkzeug:[31m[1mWARNING: This is a development server. Do not use it in a production deployment. Use a production WSGI server instead.[0m
 * Running on all addresses (0.0.0.0)
 * Running on http://127.0.0.1:5000
 * Running on http://10.106.67.2:5000
INFO:werkzeug:[33mPress CTRL+C to quit[0m
INFO:werkzeug: * Restarting with stat
WARNING:werkzeug: * Debugger is active!
INFO:werkzeug: * Debugger PIN: 518-940-869
INFO:werkzeug:127.0.0.1 - - [20/Feb/2024 11:56:43] "[35m[1mPOST /api/readgroup HTTP/1.1[0m" 500 -
INFO:werkzeug: * Detected change in '/home/amenia/Documents/Projekte/pyknx-con/main.py', reloading
INFO:werkzeug: * Restarting with stat
WARNING:werkzeug: * Debugger is active!
INFO:werkzeug: * Debugger PIN: 518-940-869
INFO:xknx.log:XKNX v2.11.2 starting tunneling connection to KNX bus.
INFO:werkzeug:127.0.0.1 - - [20/Feb/2024 11:56:53] "POST /api/readgroup HTTP/1.1" 200 -
INFO:xknx.log:XKNX v2.11.2 starting tunneling connection to KNX bus.
ERROR:xknx.log:Unexpected error while processing outgoing telegram <Telegram direction="Outgoing" source_address="0.0.6" destination_address="0/0/6" payload="<GroupValueRead />" />
Traceback (most recent call last):
  File "/usr/lib/python3.11/site-packages/xknx/core/telegram_queue.py", line 169, in _outgoing_rate_limiter
    await self.process_telegram_outgoing(telegram)
  File "/usr/lib/python3.11/site-packages/xknx/core/telegram_queue.py", line 205, in process_telegram_outgoing
    await self.xknx.cemi_handler.send_telegram(telegram)
  File "/usr/lib/python3.11/site-packages/xknx/cemi/cemi_handler.py", line 82, in send_telegram
    await self._l_data_confirmation_event.wait()
  File "/usr/lib/python3.11/asyncio/locks.py", line 210, in wait
    fut = self._get_loop().create_future()
          ^^^^^^^^^^^^^^^^
  File "/usr/lib/python3.11/asyncio/mixins.py", line 20, in _get_loop
    raise RuntimeError(f'{self!r} is bound to a different event loop')
RuntimeError: <asyncio.locks.Event object at 0x73d01d0da850 [unset]> is bound to a different event loop
WARNING:xknx.log:Error: KNX bus did not respond in time (2.0 secs) to GroupValueRead request for: 0/0/6
INFO:werkzeug:127.0.0.1 - - [20/Feb/2024 11:56:56] "[35m[1mPOST /api/readgroup HTTP/1.1[0m" 500 -
INFO:werkzeug: * Detected change in '/home/amenia/Documents/Projekte/pyknx-con/main.py', reloading
INFO:werkzeug: * Restarting with stat
WARNING:werkzeug: * Debugger is active!
INFO:werkzeug: * Debugger PIN: 518-940-869
INFO:werkzeug: * Detected change in '/home/amenia/Documents/Projekte/pyknx-con/main.py', reloading
INFO:werkzeug: * Restarting with stat
WARNING:werkzeug: * Debugger is active!
INFO:werkzeug: * Debugger PIN: 518-940-869
INFO:werkzeug:[31m[1mWARNING: This is a development server. Do not use it in a production deployment. Use a production WSGI server instead.[0m
 * Running on all addresses (0.0.0.0)
 * Running on http://127.0.0.1:5000
 * Running on http://10.106.67.2:5000
INFO:werkzeug:[33mPress CTRL+C to quit[0m
INFO:werkzeug: * Restarting with stat
WARNING:werkzeug: * Debugger is active!
INFO:werkzeug: * Debugger PIN: 518-940-869
INFO:xknx.log:XKNX v2.11.2 starting tunneling connection to KNX bus.
INFO:werkzeug:127.0.0.1 - - [20/Feb/2024 11:59:29] "POST /api/readgroup HTTP/1.1" 200 -
INFO:xknx.log:XKNX v2.11.2 starting tunneling connection to KNX bus.
ERROR:xknx.log:Unexpected error while processing outgoing telegram <Telegram direction="Outgoing" source_address="0.0.8" destination_address="0/0/6" payload="<GroupValueRead />" />
Traceback (most recent call last):
  File "/usr/lib/python3.11/site-packages/xknx/core/telegram_queue.py", line 169, in _outgoing_rate_limiter
    await self.process_telegram_outgoing(telegram)
  File "/usr/lib/python3.11/site-packages/xknx/core/telegram_queue.py", line 205, in process_telegram_outgoing
    await self.xknx.cemi_handler.send_telegram(telegram)
  File "/usr/lib/python3.11/site-packages/xknx/cemi/cemi_handler.py", line 82, in send_telegram
    await self._l_data_confirmation_event.wait()
  File "/usr/lib/python3.11/asyncio/locks.py", line 210, in wait
    fut = self._get_loop().create_future()
          ^^^^^^^^^^^^^^^^
  File "/usr/lib/python3.11/asyncio/mixins.py", line 20, in _get_loop
    raise RuntimeError(f'{self!r} is bound to a different event loop')
RuntimeError: <asyncio.locks.Event object at 0x7377580ee710 [unset]> is bound to a different event loop
WARNING:xknx.log:Error: KNX bus did not respond in time (2.0 secs) to GroupValueRead request for: 0/0/6
INFO:werkzeug:127.0.0.1 - - [20/Feb/2024 11:59:32] "[35m[1mPOST /api/readgroup HTTP/1.1[0m" 500 -
INFO:xknx.log:XKNX v2.11.2 starting tunneling connection to KNX bus.
ERROR:asyncio:_GatheringFuture exception was never retrieved
future: <_GatheringFuture finished exception=RuntimeError('<Queue at 0x7377580ee590 maxsize=0 tasks=1> is bound to a different event loop')>
Traceback (most recent call last):
  File "/usr/lib/python3.11/site-packages/xknx/core/telegram_queue.py", line 119, in _telegram_consumer
    telegram = await self.xknx.telegrams.get()
               ^^^^^^^^^^^^^^^^^^^^^^^^^^^^^^^
  File "/usr/lib/python3.11/asyncio/queues.py", line 155, in get
    getter = self._get_loop().create_future()
             ^^^^^^^^^^^^^^^^
  File "/usr/lib/python3.11/asyncio/mixins.py", line 20, in _get_loop
    raise RuntimeError(f'{self!r} is bound to a different event loop')
RuntimeError: <Queue at 0x7377580ee590 maxsize=0 tasks=1> is bound to a different event loop
INFO:werkzeug:127.0.0.1 - - [20/Feb/2024 11:59:33] "[35m[1mPOST /api/readgroup HTTP/1.1[0m" 500 -
INFO:werkzeug: * Detected change in '/home/amenia/Documents/Projekte/pyknx-con/main.py', reloading
INFO:werkzeug: * Restarting with stat
WARNING:werkzeug: * Debugger is active!
INFO:werkzeug: * Debugger PIN: 518-940-869
INFO:werkzeug: * Detected change in '/home/amenia/Documents/Projekte/pyknx-con/main.py', reloading
INFO:werkzeug: * Restarting with stat
WARNING:werkzeug: * Debugger is active!
INFO:werkzeug: * Debugger PIN: 518-940-869
INFO:werkzeug:[31m[1mWARNING: This is a development server. Do not use it in a production deployment. Use a production WSGI server instead.[0m
 * Running on all addresses (0.0.0.0)
 * Running on http://127.0.0.1:5000
 * Running on http://10.106.67.2:5000
INFO:werkzeug:[33mPress CTRL+C to quit[0m
INFO:werkzeug: * Restarting with stat
WARNING:werkzeug: * Debugger is active!
INFO:werkzeug: * Debugger PIN: 518-940-869
INFO:xknx.log:XKNX v2.11.2 starting tunneling connection to KNX bus.
INFO:werkzeug:127.0.0.1 - - [20/Feb/2024 12:01:27] "POST /api/readgroup HTTP/1.1" 200 -
INFO:xknx.log:XKNX v2.11.2 starting tunneling connection to KNX bus.
ERROR:xknx.log:Unexpected error while processing outgoing telegram <Telegram direction="Outgoing" source_address="0.0.3" destination_address="0/0/6" payload="<GroupValueRead />" />
Traceback (most recent call last):
  File "/usr/lib/python3.11/site-packages/xknx/core/telegram_queue.py", line 169, in _outgoing_rate_limiter
    await self.process_telegram_outgoing(telegram)
  File "/usr/lib/python3.11/site-packages/xknx/core/telegram_queue.py", line 205, in process_telegram_outgoing
    await self.xknx.cemi_handler.send_telegram(telegram)
  File "/usr/lib/python3.11/site-packages/xknx/cemi/cemi_handler.py", line 82, in send_telegram
    await self._l_data_confirmation_event.wait()
  File "/usr/lib/python3.11/asyncio/locks.py", line 210, in wait
    fut = self._get_loop().create_future()
          ^^^^^^^^^^^^^^^^
  File "/usr/lib/python3.11/asyncio/mixins.py", line 20, in _get_loop
    raise RuntimeError(f'{self!r} is bound to a different event loop')
RuntimeError: <asyncio.locks.Event object at 0x72edf02f2810 [unset]> is bound to a different event loop
WARNING:xknx.log:Error: KNX bus did not respond in time (2.0 secs) to GroupValueRead request for: 0/0/6
INFO:werkzeug:127.0.0.1 - - [20/Feb/2024 12:02:31] "[35m[1mPOST /api/readgroup HTTP/1.1[0m" 500 -
INFO:werkzeug: * Detected change in '/home/amenia/Documents/Projekte/pyknx-con/main.py', reloading
INFO:werkzeug: * Restarting with stat
WARNING:werkzeug: * Debugger is active!
INFO:werkzeug: * Debugger PIN: 518-940-869
INFO:werkzeug:[31m[1mWARNING: This is a development server. Do not use it in a production deployment. Use a production WSGI server instead.[0m
 * Running on all addresses (0.0.0.0)
 * Running on http://127.0.0.1:5000
 * Running on http://10.106.67.2:5000
INFO:werkzeug:[33mPress CTRL+C to quit[0m
INFO:werkzeug: * Restarting with stat
WARNING:werkzeug: * Debugger is active!
INFO:werkzeug: * Debugger PIN: 518-940-869
INFO:werkzeug:127.0.0.1 - - [20/Feb/2024 12:15:26] "[35m[1mPOST /api/readgroup HTTP/1.1[0m" 500 -
INFO:werkzeug:127.0.0.1 - - [20/Feb/2024 12:15:29] "[35m[1mPOST /api/readgroup HTTP/1.1[0m" 500 -
INFO:werkzeug: * Detected change in '/home/amenia/Documents/Projekte/pyknx-con/main.py', reloading
INFO:werkzeug: * Restarting with stat
WARNING:werkzeug: * Debugger is active!
INFO:werkzeug: * Debugger PIN: 518-940-869
INFO:werkzeug:[31m[1mWARNING: This is a development server. Do not use it in a production deployment. Use a production WSGI server instead.[0m
 * Running on all addresses (0.0.0.0)
 * Running on http://127.0.0.1:5000
 * Running on http://10.106.67.2:5000
INFO:werkzeug:[33mPress CTRL+C to quit[0m
INFO:werkzeug: * Restarting with stat
WARNING:werkzeug: * Debugger is active!
INFO:werkzeug: * Debugger PIN: 518-940-869
INFO:werkzeug:127.0.0.1 - - [20/Feb/2024 12:17:07] "[35m[1mPOST /api/readgroup HTTP/1.1[0m" 500 -
INFO:werkzeug:127.0.0.1 - - [20/Feb/2024 12:17:13] "[35m[1mPOST /api/readgroup HTTP/1.1[0m" 500 -
INFO:werkzeug:[31m[1mWARNING: This is a development server. Do not use it in a production deployment. Use a production WSGI server instead.[0m
 * Running on all addresses (0.0.0.0)
 * Running on http://127.0.0.1:5000
 * Running on http://10.106.67.2:5000
INFO:werkzeug:[33mPress CTRL+C to quit[0m
INFO:werkzeug: * Restarting with stat
WARNING:werkzeug: * Debugger is active!
INFO:werkzeug: * Debugger PIN: 518-940-869
INFO:werkzeug:127.0.0.1 - - [20/Feb/2024 12:17:18] "[35m[1mPOST /api/readgroup HTTP/1.1[0m" 500 -
INFO:werkzeug: * Detected change in '/home/amenia/Documents/Projekte/pyknx-con/main.py', reloading
INFO:werkzeug: * Restarting with stat
WARNING:werkzeug: * Debugger is active!
INFO:werkzeug: * Debugger PIN: 518-940-869
INFO:werkzeug:[31m[1mWARNING: This is a development server. Do not use it in a production deployment. Use a production WSGI server instead.[0m
 * Running on all addresses (0.0.0.0)
 * Running on http://127.0.0.1:5000
 * Running on http://10.106.67.2:5000
INFO:werkzeug:[33mPress CTRL+C to quit[0m
INFO:werkzeug: * Restarting with stat
WARNING:werkzeug: * Debugger is active!
INFO:werkzeug: * Debugger PIN: 518-940-869
INFO:werkzeug:127.0.0.1 - - [20/Feb/2024 12:17:32] "[35m[1mPOST /api/readgroup HTTP/1.1[0m" 500 -
INFO:werkzeug:127.0.0.1 - - [20/Feb/2024 12:17:33] "[35m[1mPOST /api/readgroup HTTP/1.1[0m" 500 -
INFO:werkzeug:[31m[1mWARNING: This is a development server. Do not use it in a production deployment. Use a production WSGI server instead.[0m
 * Running on all addresses (0.0.0.0)
 * Running on http://127.0.0.1:5000
 * Running on http://10.106.67.2:5000
INFO:werkzeug:[33mPress CTRL+C to quit[0m
INFO:werkzeug: * Restarting with stat
WARNING:werkzeug: * Debugger is active!
INFO:werkzeug: * Debugger PIN: 518-940-869
INFO:werkzeug:127.0.0.1 - - [20/Feb/2024 12:17:39] "[35m[1mPOST /api/readgroup HTTP/1.1[0m" 500 -
INFO:werkzeug: * Detected change in '/home/amenia/Documents/Projekte/pyknx-con/main.py', reloading
INFO:werkzeug: * Restarting with stat
INFO:werkzeug:[31m[1mWARNING: This is a development server. Do not use it in a production deployment. Use a production WSGI server instead.[0m
 * Running on all addresses (0.0.0.0)
 * Running on http://127.0.0.1:5000
 * Running on http://10.106.67.2:5000
INFO:werkzeug:[33mPress CTRL+C to quit[0m
INFO:werkzeug: * Restarting with stat
WARNING:werkzeug: * Debugger is active!
INFO:werkzeug: * Debugger PIN: 518-940-869
INFO:werkzeug:127.0.0.1 - - [20/Feb/2024 12:18:02] "[35m[1mPOST /api/readgroup HTTP/1.1[0m" 500 -
INFO:werkzeug: * Detected change in '/home/amenia/Documents/Projekte/pyknx-con/main.py', reloading
INFO:werkzeug: * Restarting with stat
WARNING:werkzeug: * Debugger is active!
INFO:werkzeug: * Debugger PIN: 518-940-869
INFO:werkzeug:[31m[1mWARNING: This is a development server. Do not use it in a production deployment. Use a production WSGI server instead.[0m
 * Running on all addresses (0.0.0.0)
 * Running on http://127.0.0.1:5000
 * Running on http://10.106.67.2:5000
INFO:werkzeug:[33mPress CTRL+C to quit[0m
INFO:werkzeug: * Restarting with stat
WARNING:werkzeug: * Debugger is active!
INFO:werkzeug: * Debugger PIN: 518-940-869
INFO:xknx.log:XKNX v2.11.2 starting tunneling connection to KNX bus.
INFO:werkzeug:127.0.0.1 - - [20/Feb/2024 12:22:38] "POST /api/readgroup HTTP/1.1" 200 -
INFO:xknx.log:XKNX v2.11.2 starting tunneling connection to KNX bus.
ERROR:xknx.log:Unexpected error while processing outgoing telegram <Telegram direction="Outgoing" source_address="0.0.5" destination_address="0/0/6" payload="<GroupValueRead />" />
Traceback (most recent call last):
  File "/usr/lib/python3.11/site-packages/xknx/core/telegram_queue.py", line 169, in _outgoing_rate_limiter
    await self.process_telegram_outgoing(telegram)
  File "/usr/lib/python3.11/site-packages/xknx/core/telegram_queue.py", line 205, in process_telegram_outgoing
    await self.xknx.cemi_handler.send_telegram(telegram)
  File "/usr/lib/python3.11/site-packages/xknx/cemi/cemi_handler.py", line 82, in send_telegram
    await self._l_data_confirmation_event.wait()
  File "/usr/lib/python3.11/asyncio/locks.py", line 210, in wait
    fut = self._get_loop().create_future()
          ^^^^^^^^^^^^^^^^
  File "/usr/lib/python3.11/asyncio/mixins.py", line 20, in _get_loop
    raise RuntimeError(f'{self!r} is bound to a different event loop')
RuntimeError: <asyncio.locks.Event object at 0x725cb19ea990 [unset]> is bound to a different event loop
WARNING:xknx.log:Error: KNX bus did not respond in time (2.0 secs) to GroupValueRead request for: 0/0/6
INFO:werkzeug:127.0.0.1 - - [20/Feb/2024 12:22:41] "[35m[1mPOST /api/readgroup HTTP/1.1[0m" 500 -
INFO:werkzeug: * Detected change in '/home/amenia/Documents/Projekte/pyknx-con/main.py', reloading
INFO:werkzeug: * Restarting with stat
WARNING:werkzeug: * Debugger is active!
INFO:werkzeug: * Debugger PIN: 518-940-869
INFO:werkzeug:[31m[1mWARNING: This is a development server. Do not use it in a production deployment. Use a production WSGI server instead.[0m
 * Running on all addresses (0.0.0.0)
 * Running on http://127.0.0.1:5000
 * Running on http://10.106.67.2:5000
INFO:werkzeug:[33mPress CTRL+C to quit[0m
INFO:werkzeug: * Restarting with stat
WARNING:werkzeug: * Debugger is active!
INFO:werkzeug: * Debugger PIN: 518-940-869
INFO:xknx.log:XKNX v2.11.2 starting tunneling connection to KNX bus.
INFO:werkzeug:127.0.0.1 - - [20/Feb/2024 12:23:13] "POST /api/readgroup HTTP/1.1" 200 -
INFO:xknx.log:XKNX v2.11.2 starting tunneling connection to KNX bus.
INFO:werkzeug:127.0.0.1 - - [20/Feb/2024 12:23:15] "POST /api/readgroup HTTP/1.1" 200 -
INFO:xknx.log:XKNX v2.11.2 starting tunneling connection to KNX bus.
INFO:werkzeug:127.0.0.1 - - [20/Feb/2024 12:23:16] "POST /api/readgroup HTTP/1.1" 200 -
INFO:werkzeug: * Detected change in '/home/amenia/Documents/Projekte/pyknx-con/main.py', reloading
INFO:werkzeug: * Restarting with stat
WARNING:werkzeug: * Debugger is active!
INFO:werkzeug: * Debugger PIN: 518-940-869
